joblib.externals.loky.process_executor._RemoteTraceback: 
"""
Traceback (most recent call last):
  File "/home/m448735/anaconda3/lib/python3.8/site-packages/joblib/externals/loky/process_executor.py", line 431, in _process_worker
    r = call_item()
  File "/home/m448735/anaconda3/lib/python3.8/site-packages/joblib/externals/loky/process_executor.py", line 285, in __call__
    return self.fn(*self.args, **self.kwargs)
  File "/home/m448735/anaconda3/lib/python3.8/site-packages/joblib/_parallel_backends.py", line 595, in __call__
    return self.func(*args, **kwargs)
  File "/home/m448735/anaconda3/lib/python3.8/site-packages/joblib/parallel.py", line 262, in __call__
    return [func(*args, **kwargs)
  File "/home/m448735/anaconda3/lib/python3.8/site-packages/joblib/parallel.py", line 262, in <listcomp>
    return [func(*args, **kwargs)
  File "/home/m448735/anaconda3/lib/python3.8/site-packages/sklearn/model_selection/_validation.py", line 531, in _fit_and_score
    estimator.fit(X_train, y_train, **fit_params)
  File "/home/m448735/anaconda3/lib/python3.8/site-packages/catboost/core.py", line 4539, in fit
    self._fit(X, y, cat_features, text_features, embedding_features, None, sample_weight, None, None, None, None, baseline, use_best_model,
  File "/home/m448735/anaconda3/lib/python3.8/site-packages/catboost/core.py", line 1904, in _fit
    train_params = self._prepare_train_params(
  File "/home/m448735/anaconda3/lib/python3.8/site-packages/catboost/core.py", line 1836, in _prepare_train_params
    _check_train_params(params)
  File "_catboost.pyx", line 5561, in _catboost._check_train_params
  File "_catboost.pyx", line 5580, in _catboost._check_train_params
_catboost.CatBoostError: catboost/private/libs/options/oblivious_tree_options.cpp:120: Maximum tree depth is 16
"""

The above exception was the direct cause of the following exception:

Traceback (most recent call last):
  File "node_2.py", line 3, in <module>
    experiments.exp_14()
  File "/home/m448735/hyperparameter-tuning-benchmark/Experiments/experiments.py", line 163, in exp_14
    hasil=opt.optimized_bayesian_search(X,y,model,parameter,seed)
  File "/home/m448735/hyperparameter-tuning-benchmark/Experiments/services/optimize.py", line 64, in optimized_bayesian_search
    search.fit(X,y)
  File "/home/m448735/anaconda3/lib/python3.8/site-packages/skopt/searchcv.py", line 692, in fit
    optim_result = self._step(
  File "/home/m448735/anaconda3/lib/python3.8/site-packages/skopt/searchcv.py", line 579, in _step
    self._fit(X, y, groups, params_dict)
  File "/home/m448735/anaconda3/lib/python3.8/site-packages/skopt/searchcv.py", line 410, in _fit
    out = Parallel(
  File "/home/m448735/anaconda3/lib/python3.8/site-packages/joblib/parallel.py", line 1061, in __call__
    self.retrieve()
  File "/home/m448735/anaconda3/lib/python3.8/site-packages/joblib/parallel.py", line 940, in retrieve
    self._output.extend(job.get(timeout=self.timeout))
  File "/home/m448735/anaconda3/lib/python3.8/site-packages/joblib/_parallel_backends.py", line 542, in wrap_future_result
    return future.result(timeout=timeout)
  File "/home/m448735/anaconda3/lib/python3.8/concurrent/futures/_base.py", line 439, in result
    return self.__get_result()
  File "/home/m448735/anaconda3/lib/python3.8/concurrent/futures/_base.py", line 388, in __get_result
    raise self._exception
_catboost.CatBoostError: catboost/private/libs/options/oblivious_tree_options.cpp:120: Maximum tree depth is 16
srun: error: komputasi06: task 0: Exited with exit code 1
