Traceback (most recent call last):
  File "experiment_3_xgboost_bank_randomsearch.py", line 12, in <module>
    hasil=opt.optimized_random_search(X,y,model,parameter,seed)
  File "/home/m448735/hyperparameter-tuning-benchmark/Experiments/services/optimize.py", line 50, in optimized_random_search
    search.fit(X,y)
  File "/home/m448735/anaconda3/lib/python3.8/site-packages/sklearn/utils/validation.py", line 72, in inner_f
    return f(**kwargs)
  File "/home/m448735/anaconda3/lib/python3.8/site-packages/sklearn/model_selection/_search.py", line 736, in fit
    self._run_search(evaluate_candidates)
  File "/home/m448735/anaconda3/lib/python3.8/site-packages/sklearn/model_selection/_search.py", line 1529, in _run_search
    evaluate_candidates(ParameterSampler(
  File "/home/m448735/anaconda3/lib/python3.8/site-packages/sklearn/model_selection/_search.py", line 700, in evaluate_candidates
    candidate_params = list(candidate_params)
  File "/home/m448735/anaconda3/lib/python3.8/site-packages/sklearn/model_selection/_search.py", line 269, in __iter__
    rng = check_random_state(self.random_state)
  File "/home/m448735/anaconda3/lib/python3.8/site-packages/sklearn/utils/validation.py", line 867, in check_random_state
    raise ValueError('%r cannot be used to seed a numpy.random.RandomState'
ValueError: [1] cannot be used to seed a numpy.random.RandomState instance
srun: error: komputasi06: task 0: Exited with exit code 1
